Workbook
Name cfg_Site: 'Control Panel'!$C$7
Name cfg_AsOf: 'Control Panel'!$C$8
Name cfg_Low: 'Control Panel'!$C$11
Name cfg_Crit: 'Control Panel'!$C$12
Name cfg_Lead: 'Control Panel'!$C$13
Name cfg_ExpiryWarn: 'Control Panel'!$C$14
Name cfg_OrderMonth: 'Control Panel'!$C$15
Name cfg_ReorderOK: 'Control Panel'!$C$16
Name cfg_PilotStart: 'Control Panel'!$C$19
Name cfg_PilotDays: 'Control Panel'!$C$20
Name cfg_PilotEnd: 'Control Panel'!$C$21
Name cfg_PilotWeeks: 'Control Panel'!$C$22
Name cfg_MinFeedback: 'Control Panel'!$C$25
Name cfg_ExpandRating: 'Control Panel'!$C$26
Name cfg_ExpandPositive: 'Control Panel'!$C$27
Name cfg_ContinueRating: 'Control Panel'!$C$28
Name StaffList: OFFSET('Control Panel'!$F$9,0,0,MAX(1,COUNTA('Control Panel'!$F$9:$F$38)),1)
Name TeamList: OFFSET('Control Panel'!$G$9,0,0,MAX(1,COUNTA('Control Panel'!$G$9:$G$38)),1)
Name SnackCats: 'Control Panel'!$H$9:$H$38
Name BevCats: 'Control Panel'!$I$9:$I$38
Name SrcCount: COUNTA('Source Data'!$C$6:$C$305)
Name MS_Name: 'Inventory Master'!$C$6:$C$305
Name MS_Status: 'Inventory Master'!$J$6:$J$305
Name MS_Stock: 'Inventory Master'!$H$6:$H$305
Name MS_PAR: 'Inventory Master'!$E$6:$E$305
Name MS_Pct: 'Inventory Master'!$I$6:$I$305
Name MS_Sugg: 'Inventory Master'!$K$6:$K$305
Name MS_Cat: 'Inventory Master'!$B$6:$B$305
Name MS_Exp: 'Inventory Master'!$O$6:$O$305
Name MS_ExpDays: 'Inventory Master'!$P$6:$P$305
Name MS_ExpStatus: 'Inventory Master'!$Q$6:$Q$305
Name CL_Date: 'Weekly Count'!$B$6:$B$3005
Name CL_Prod: 'Weekly Count'!$D$6:$D$3005
Name CL_Count: 'Weekly Count'!$F$6:$F$3005
Name CL_Key: 'Weekly Count'!$O$6:$O$3005
Name OL_Cat: 'Order List'!$B$6:$B$305
Name OL_Qty: 'Order List'!$G$6:$G$305
Name OL_Flag: 'Order List'!$L$6:$L$305
Name OL_Priority: 'Order List'!$K$6:$K$305
Name OL_Cost: 'Order List'!$O$6:$O$305
Name PP_Name: 'Pilot Products'!$B$6:$B$85
Name PP_Type: 'Pilot Products'!$E$6:$E$85
Name PP_Flag: 'Pilot Products'!$H$6:$H$85
Name PP_Units: 'Pilot Products'!$N$6:$N$85
Name RL_Date: 'Restock Log'!$B$6:$B$1505
Name RL_Prod: 'Restock Log'!$D$6:$D$1505
Name RL_Type: 'Restock Log'!$E$6:$E$1505
Name RL_Before: 'Restock Log'!$F$6:$F$1505
Name RL_Added: 'Restock Log'!$G$6:$G$1505
Name RL_After: 'Restock Log'!$H$6:$H$1505
Name RL_Days: 'Restock Log'!$K$6:$K$1505
Name RL_Hours: 'Restock Log'!$L$6:$L$1505
Name RL_Day: 'Restock Log'!$N$6:$N$1505
Name RL_Key: 'Restock Log'!$P$6:$P$1505
Name RL_TS: 'Restock Log'!$R$6:$R$1505
Name FB_Date: 'Feedback Log'!$B$6:$B$1005
Name FB_Type: 'Feedback Log'!$D$6:$D$1005
Name FB_Rating: 'Feedback Log'!$E$6:$E$1005
Name FB_Prod: 'Feedback Log'!$F$6:$F$1005
Name FB_FollowUp: 'Feedback Log'!$I$6:$I$1005

Sheet Home
B1: =cfg_Site&" Operations Hub · Home" | O1: =cfg_AsOf
B2: ⌂ HOME | D2: ⚙ CONTROL | E2: INVENTORY | F2: ✎ COUNT | H2: ✎ RECEIVE | I2: ORDERS | J2: ◧ INV. DASH | L2: PILOT ITEMS | M2: ✎ RESTOCK | N2: ✎ FEEDBACK | P2: ◧ PILOT DASH | Q2: ✎ TASKS
B3: Pick a module below. Only counts, deliveries, refills, feedback and tasks are typed by hand; everything else runs itself.
B6: =IF(SrcCount=0,"NO PRODUCTS LOADED — open Source Data and paste Category, Item Name, Item #, Recent Date Received, Expiration Date and PAR Value.","")
B7: RIGHT NOW
B8: CRITICAL ITEMS | F8: ITEMS TO ORDER | J8: PILOT DAY | N8: PILOT SIGNAL
B9: =COUNTIF(MS_Status,"CRITICAL") | F9: =COUNTIF(OL_Flag,"ORDER") | J9: =IF(cfg_AsOf<cfg_PilotStart,0,MIN(cfg_AsOf-cfg_PilotStart+1,cfg_PilotDays)) | N9: =Pilot_Rec
B12: ALERTS
B13: Critical items (order now) | L13: =COUNTIF(MS_Status,"CRITICAL") | N13: =IF(ISNUMBER(L13),IF(L13>0,"ACTION","CLEAR"),"ACTION") | P13: Open ›
B14: Expired products | L14: =COUNTIF(MS_ExpStatus,"EXPIRED") | N14: =IF(ISNUMBER(L14),IF(L14>0,"ACTION","CLEAR"),"ACTION") | P14: Open ›
B15: ="Products expiring within "&cfg_ExpiryWarn&" days" | L15: =COUNTIF(MS_ExpStatus,"EXPIRING") | N15: =IF(ISNUMBER(L15),IF(L15>0,"ACTION","CLEAR"),"ACTION") | P15: Open ›
B16: Days since the last weekly count | L16: =IF(MAX(CL_Date)=0,"No count yet",cfg_AsOf-MAX(CL_Date)) | N16: =IF(ISNUMBER(L16),IF(L16>7,"ACTION","CLEAR"),"ACTION") | P16: Open ›
B17: Overdue tasks | L17: =COUNTIF(TK_Flag,"OVERDUE") | N17: =IF(ISNUMBER(L17),IF(L17>0,"ACTION","CLEAR"),"ACTION") | P17: Open ›
B18: Open feedback follow-ups | L18: =COUNTIFS(FB_FollowUp,"Yes",FB_Status,"<>Closed") | N18: =IF(ISNUMBER(L18),IF(L18>0,"ACTION","CLEAR"),"ACTION") | P18: Open ›
B20: SYSTEM 1 · INVENTORY MANAGEMENT
B21: CONTROL PANEL | F21: INVENTORY MASTER | J21: ✎ WEEKLY COUNT | N21: ORDER LIST
B22: Thresholds, lead time, order month, pilot dates, lists. | F22: Every product with stock %, status, expiry and suggested order. | J22: Log the weekly physical count here. | N22: Auto-built purchase list with priority, supplier and cost.
B24: INVENTORY DASHBOARD | F24: ✎ RECEIVING LOG | J24: SOURCE DATA
B25: KPIs, status mix, orders by category, expiry watch. | F25: Log deliveries; received units are added to stock. | J25: Product master, suppliers and costs (swap it for another office).
B28: SYSTEM 2 · 60-DAY PANTRY PILOT
B29: PILOT PRODUCTS | F29: ✎ RESTOCK LOG | J29: ✎ FEEDBACK LOG | N29: PILOT DASHBOARD
B30: Snacks & beverages in the pantry with usage stats. | F30: Log every refill (date, time, qty). | J30: Log employee feedback and follow-ups. | N30: Leadership view and continue / expand / adjust signal.
B33: OFFICE
B34: ✎ TASKS
B35: Office work with owners, due dates and overdue flags.
B38: YOUR ROUTINE (a few entries per week)
B39: 1 | C39: Every week | E39: Weekly Count: date, product, quantity, your name. Status, usage and the order list update automatically.
B40: 2 | C40: Each delivery | E40: Receiving Log: date, product, quantity received. It is added to stock.
B41: 3 | C41: Every refill | E41: Restock Log: date, time, product, qty before, qty added, your name.
B42: 4 | C42: Any feedback | E42: Feedback Log: type, rating, product, comment, team, follow-up.
B43: 5 | C43: Monthly | E43: Order List → filter Order Flag = ORDER and place the order.
C45: Blue = your entries | I45: Yellow = one-time setup | N45: White = automatic

Sheet Control Panel
B1: =cfg_Site&" Operations Hub · Control Panel" | O1: =cfg_AsOf
B2: ⌂ HOME | C2: ⚙ CONTROL | D2: INVENTORY | E2: ✎ COUNT | G2: ✎ RECEIVE | H2: ORDERS | I2: ◧ INV. DASH | J2: PILOT ITEMS | K2: ✎ RESTOCK | L2: ✎ FEEDBACK | N2: ◧ PILOT DASH | O2: ✎ TASKS
B3: Every global setting lives here. Change a yellow cell once and all sheets, statuses, orders and dashboards recalculate.
B6: GENERAL | F6: LISTS (dropdown sources — edit anytime)
B7: Site / office name | C7: SJUB | D7: Shown in every title bar. | F7: STAFF | G7: AREAS / TEAMS | H7: SNACK CATEGORIES | I7: BEVERAGE CATEGORIES
B8: Report date (as of) | C8: =TODAY() | D8: Leave as =TODAY() for live reporting, or type a date to report as of that day. | F8: Names for Counted By / Refilled By / Owner | G8: Used by the Feedback Log | H8: Source categories placed in the pantry as Snack | I8: Source categories placed as Beverage
G9: Front Office | H9: Popcorn | I9: Coffee
B10: SYSTEM 1 · INVENTORY RULES | G10: Operations | H10: Pretzels . Crackers. Chips | I10: Teabags
B11: Low-stock threshold (% of PAR) | C11: 0.5 | D11: At or below this share of PAR an item turns LOW (amber). | G11: Administration | H11: Nut
B12: Critical threshold (% of PAR) | C12: 0.25 | D12: At or below this share of PAR an item turns CRITICAL (red). | H12: Cookie. Biscuit
B13: Supplier lead time (days) | C13: 7 | D13: Used to calculate Need-By dates on the order list. | H13: Candy
B14: Expiry warning window (days) | C14: 30 | D14: Items expiring within this many days are flagged EXPIRING. | H14: Healthy Snacks
B15: Order month | C15: =DATE(YEAR(cfg_AsOf),MONTH(cfg_AsOf),1) | D15: Defaults to the report month automatically; type a date to plan another month.
B16: Also reorder OK items below PAR? | C16: No | D16: No = order only LOW and CRITICAL items. Yes = top every item up to PAR.
B18: SYSTEM 2 · PANTRY PILOT
B19: Pilot start date | C19: 46293 | D19: Day 1 of the pilot.
B20: Pilot duration (days) | C20: 60 | D20: Calendar days, including the start and end dates.
B21: Pilot end date | C21: =cfg_PilotStart+cfg_PilotDays-1 | D21: Calculated: start + duration − 1.
B22: Pilot weeks | C22: =ROUNDUP(cfg_PilotDays/7,0) | D22: Calculated.
B24: PILOT DECISION RULES (drive the leadership recommendation)
B25: Minimum feedback entries for a decision | C25: 10 | D25: Below this the dashboard says GATHER MORE DATA.
B26: EXPAND if average rating ≥ | C26: 4.2 | D26: …and positive share at or above the next setting.
B27: EXPAND if positive feedback ≥ | C27: 0.6
B28: CONTINUE if average rating ≥ | C28: 3.5 | D28: Below this the recommendation is ADJUST.
B41: HOW THIS WORKBOOK IS COLOR-CODED
B42: Blue cells | C42: Your weekly entries: physical counts, refills, feedback.
B43: Yellow cells | C43: One-time setup: settings, lists and the source product file.
B44: Grey / white cells | C44: Calculated automatically. Locked — never type here.

Sheet Inventory Master
B1: =cfg_Site&" Operations Hub · Inventory Management" | S1: =cfg_AsOf
B2: ⌂ HOME | C2: ⚙ CONTROL | D2: INVENTORY | E2: ✎ COUNT | G2: ✎ RECEIVE | I2: ORDERS | K2: ◧ INV. DASH | M2: PILOT ITEMS | N2: ✎ RESTOCK | P2: ✎ FEEDBACK | R2: ◧ PILOT DASH | T2: ✎ TASKS
B3: One row per product, built from Source Data. Current stock = latest count + units received after it (Receiving Log). Status: OK › LOW › CRITICAL using the Control Panel thresholds. Nothing on this page is typed by hand.
B5: Category | C5: Item Name | D5: Item # | E5: PAR Level | F5: Starting Qty | G5: Latest Count | H5: Current Stock | I5: Stock % | J5: Status | K5: Suggested Order Qty | L5: Last Count Date | M5: Last Received Date | N5: Counts Logged | O5: Expiration Date | P5: Days to Expiry | Q5: Expiry Status | R5: Received Since Count | S5: Supplier | T5: Unit Cost
B6: ='_Engine'!B2 | C6: ='_Engine'!C2 | D6: ='_Engine'!D2 | E6: ='_Engine'!G2 | F6: =IF(OR($C6="",N6=0),"",INDEX(CL_Count,MATCH('_Engine'!E2&"|1",CL_Key,0))) | G6: =IF(OR($C6="",N6=0),"",INDEX(CL_Count,MATCH('_Engine'!E2&"|"&N6,CL_Key,0))) | H6: =IF(OR($C6="",G6=""),"",G6+N(R6)) | I6: =IF(OR(H6="",E6="",N(E6)=0),"",H6/E6) | J6: =IF($C6="","",IF(H6="","NO COUNT",IF(OR(E6="",N(E6)=0),"NO PAR",IF(I6<=cfg_Crit,"CRITICAL",IF(I6<=cfg_Low,"LOW","OK"))))) | K6: =IF(OR($C6="",H6="",E6=""),"",MAX(0,E6-H6)) | L6: =IF(OR($C6="",N6=0),"",INDEX(CL_Date,MATCH('_Engine'!E2&"|"&N6,CL_Key,0))) | M6: ='_Engine'!F2 | N6: =IF($C6="","",COUNTIFS(CL_Prod,'_Engine'!E2,CL_Count,"<>")) | O6: ='_Engine'!L2 | P6: =IF(ISNUMBER(O6),O6-cfg_AsOf,"") | Q6: =IF($C6="","",IF(NOT(ISNUMBER(O6)),"N/A",IF(P6<0,"EXPIRED",IF(P6<=cfg_ExpiryWarn,"EXPIRING","OK")))) | R6: =IF(OR($C6="",L6=""),"",SUMIFS(RC_Qty,RC_Prod,'_Engine'!E2,RC_Date,">"&L6)) | S6: ='_Engine'!AC2 | T6: ='_Engine'!AD2
B7: ='_Engine'!B3 | C7: ='_Engine'!C3 | D7: ='_Engine'!D3 | E7: ='_Engine'!G3 | F7: =IF(OR($C7="",N7=0),"",INDEX(CL_Count,MATCH('_Engine'!E3&"|1",CL_Key,0))) | G7: =IF(OR($C7="",N7=0),"",INDEX(CL_Count,MATCH('_Engine'!E3&"|"&N7,CL_Key,0))) | H7: =IF(OR($C7="",G7=""),"",G7+N(R7)) | I7: =IF(OR(H7="",E7="",N(E7)=0),"",H7/E7) | J7: =IF($C7="","",IF(H7="","NO COUNT",IF(OR(E7="",N(E7)=0),"NO PAR",IF(I7<=cfg_Crit,"CRITICAL",IF(I7<=cfg_Low,"LOW","OK"))))) | K7: =IF(OR($C7="",H7="",E7=""),"",MAX(0,E7-H7)) | L7: =IF(OR($C7="",N7=0),"",INDEX(CL_Date,MATCH('_Engine'!E3&"|"&N7,CL_Key,0))) | M7: ='_Engine'!F3 | N7: =IF($C7="","",COUNTIFS(CL_Prod,'_Engine'!E3,CL_Count,"<>")) | O7: ='_Engine'!L3 | P7: =IF(ISNUMBER(O7),O7-cfg_AsOf,"") | Q7: =IF($C7="","",IF(NOT(ISNUMBER(O7)),"N/A",IF(P7<0,"EXPIRED",IF(P7<=cfg_ExpiryWarn,"EXPIRING","OK")))) | R7: =IF(OR($C7="",L7=""),"",SUMIFS(RC_Qty,RC_Prod,'_Engine'!E3,RC_Date,">"&L7)) | S7: ='_Engine'!AC3 | T7: ='_Engine'!AD3
B8: ='_Engine'!B4 | C8: ='_Engine'!C4 | D8: ='_Engine'!D4 | E8: ='_Engine'!G4 | F8: =IF(OR($C8="",N8=0),"",INDEX(CL_Count,MATCH('_Engine'!E4&"|1",CL_Key,0))) | G8: =IF(OR($C8="",N8=0),"",INDEX(CL_Count,MATCH('_Engine'!E4&"|"&N8,CL_Key,0))) | H8: =IF(OR($C8="",G8=""),"",G8+N(R8)) | I8: =IF(OR(H8="",E8="",N(E8)=0),"",H8/E8) | J8: =IF($C8="","",IF(H8="","NO COUNT",IF(OR(E8="",N(E8)=0),"NO PAR",IF(I8<=cfg_Crit,"CRITICAL",IF(I8<=cfg_Low,"LOW","OK"))))) | K8: =IF(OR($C8="",H8="",E8=""),"",MAX(0,E8-H8)) | L8: =IF(OR($C8="",N8=0),"",INDEX(CL_Date,MATCH('_Engine'!E4&"|"&N8,CL_Key,0))) | M8: ='_Engine'!F4 | N8: =IF($C8="","",COUNTIFS(CL_Prod,'_Engine'!E4,CL_Count,"<>")) | O8: ='_Engine'!L4 | P8: =IF(ISNUMBER(O8),O8-cfg_AsOf,"") | Q8: =IF($C8="","",IF(NOT(ISNUMBER(O8)),"N/A",IF(P8<0,"EXPIRED",IF(P8<=cfg_ExpiryWarn,"EXPIRING","OK")))) | R8: =IF(OR($C8="",L8=""),"",SUMIFS(RC_Qty,RC_Prod,'_Engine'!E4,RC_Date,">"&L8)) | S8: ='_Engine'!AC4 | T8: ='_Engine'!AD4
B9: ='_Engine'!B5 | C9: ='_Engine'!C5 | D9: ='_Engine'!D5 | E9: ='_Engine'!G5 | F9: =IF(OR($C9="",N9=0),"",INDEX(CL_Count,MATCH('_Engine'!E5&"|1",CL_Key,0))) | G9: =IF(OR($C9="",N9=0),"",INDEX(CL_Count,MATCH('_Engine'!E5&"|"&N9,CL_Key,0))) | H9: =IF(OR($C9="",G9=""),"",G9+N(R9)) | I9: =IF(OR(H9="",E9="",N(E9)=0),"",H9/E9) | J9: =IF($C9="","",IF(H9="","NO COUNT",IF(OR(E9="",N(E9)=0),"NO PAR",IF(I9<=cfg_Crit,"CRITICAL",IF(I9<=cfg_Low,"LOW","OK"))))) | K9: =IF(OR($C9="",H9="",E9=""),"",MAX(0,E9-H9)) | L9: =IF(OR($C9="",N9=0),"",INDEX(CL_Date,MATCH('_Engine'!E5&"|"&N9,CL_Key,0))) | M9: ='_Engine'!F5 | N9: =IF($C9="","",COUNTIFS(CL_Prod,'_Engine'!E5,CL_Count,"<>")) | O9: ='_Engine'!L5 | P9: =IF(ISNUMBER(O9),O9-cfg_AsOf,"") | Q9: =IF($C9="","",IF(NOT(ISNUMBER(O9)),"N/A",IF(P9<0,"EXPIRED",IF(P9<=cfg_ExpiryWarn,"EXPIRING","OK")))) | R9: =IF(OR($C9="",L9=""),"",SUMIFS(RC_Qty,RC_Prod,'_Engine'!E5,RC_Date,">"&L9)) | S9: ='_Engine'!AC5 | T9: ='_Engine'!AD5
B10: ='_Engine'!B6 | C10: ='_Engine'!C6 | D10: ='_Engine'!D6 | E10: ='_Engine'!G6 | F10: =IF(OR($C10="",N10=0),"",INDEX(CL_Count,MATCH('_Engine'!E6&"|1",CL_Key,0))) | G10: =IF(OR($C10="",N10=0),"",INDEX(CL_Count,MATCH('_Engine'!E6&"|"&N10,CL_Key,0))) | H10: =IF(OR($C10="",G10=""),"",G10+N(R10)) | I10: =IF(OR(H10="",E10="",N(E10)=0),"",H10/E10) | J10: =IF($C10="","",IF(H10="","NO COUNT",IF(OR(E10="",N(E10)=0),"NO PAR",IF(I10<=cfg_Crit,"CRITICAL",IF(I10<=cfg_Low,"LOW","OK"))))) | K10: =IF(OR($C10="",H10="",E10=""),"",MAX(0,E10-H10)) | L10: =IF(OR($C10="",N10=0),"",INDEX(CL_Date,MATCH('_Engine'!E6&"|"&N10,CL_Key,0))) | M10: ='_Engine'!F6 | N10: =IF($C10="","",COUNTIFS(CL_Prod,'_Engine'!E6,CL_Count,"<>")) | O10: ='_Engine'!L6 | P10: =IF(ISNUMBER(O10),O10-cfg_AsOf,"") | Q10: =IF($C10="","",IF(NOT(ISNUMBER(O10)),"N/A",IF(P10<0,"EXPIRED",IF(P10<=cfg_ExpiryWarn,"EXPIRING","OK")))) | R10: =IF(OR($C10="",L10=""),"",SUMIFS(RC_Qty,RC_Prod,'_Engine'!E6,RC_Date,">"&L10)) | S10: ='_Engine'!AC6 | T10: ='_Engine'!AD6
B11: ='_Engine'!B7 | C11: ='_Engine'!C7 | D11: ='_Engine'!D7 | E11: ='_Engine'!G7 | F11: =IF(OR($C11="",N11=0),"",INDEX(CL_Count,MATCH('_Engine'!E7&"|1",CL_Key,0))) | G11: =IF(OR($C11="",N11=0),"",INDEX(CL_Count,MATCH('_Engine'!E7&"|"&N11,CL_Key,0))) | H11: =IF(OR($C11="",G11=""),"",G11+N(R11)) | I11: =IF(OR(H11="",E11="",N(E11)=0),"",H11/E11) | J11: =IF($C11="","",IF(H11="","NO COUNT",IF(OR(E11="",N(E11)=0),"NO PAR",IF(I11<=cfg_Crit,"CRITICAL",IF(I11<=cfg_Low,"LOW","OK"))))) | K11: =IF(OR($C11="",H11="",E11=""),"",MAX(0,E11-H11)) | L11: =IF(OR($C11="",N11=0),"",INDEX(CL_Date,MATCH('_Engine'!E7&"|"&N11,CL_Key,0))) | M11: ='_Engine'!F7 | N11: =IF($C11="","",COUNTIFS(CL_Prod,'_Engine'!E7,CL_Count,"<>")) | O11: ='_Engine'!L7 | P11: =IF(ISNUMBER(O11),O11-cfg_AsOf,"") | Q11: =IF($C11="","",IF(NOT(ISNUMBER(O11)),"N/A",IF(P11<0,"EXPIRED",IF(P11<=cfg_ExpiryWarn,"EXPIRING","OK")))) | R11: =IF(OR($C11="",L11=""),"",SUMIFS(RC_Qty,RC_Prod,'_Engine'!E7,RC_Date,">"&L11)) | S11: ='_Engine'!AC7 | T11: ='_Engine'!AD7
B12: ='_Engine'!B8 | C12: ='_Engine'!C8 | D12: ='_Engine'!D8 | E12: ='_Engine'!G8 | F12: =IF(OR($C12="",N12=0),"",INDEX(CL_Count,MATCH('_Engine'!E8&"|1",CL_Key,0))) | G12: =IF(OR($C12="",N12=0),"",INDEX(CL_Count,MATCH('_Engine'!E8&"|"&N12,CL_Key,0))) | H12: =IF(OR($C12="",G12=""),"",G12+N(R12)) | I12: =IF(OR(H12="",E12="",N(E12)=0),"",H12/E12) | J12: =IF($C12="","",IF(H12="","NO COUNT",IF(OR(E12="",N(E12)=0),"NO PAR",IF(I12<=cfg_Crit,"CRITICAL",IF(I12<=cfg_Low,"LOW","OK"))))) | K12: =IF(OR($C12="",H12="",E12=""),"",MAX(0,E12-H12)) | L12: =IF(OR($C12="",N12=0),"",INDEX(CL_Date,MATCH('_Engine'!E8&"|"&N12,CL_Key,0))) | M12: ='_Engine'!F8 | N12: =IF($C12="","",COUNTIFS(CL_Prod,'_Engine'!E8,CL_Count,"<>")) | O12: ='_Engine'!L8 | P12: =IF(ISNUMBER(O12),O12-cfg_AsOf,"") | Q12: =IF($C12="","",IF(NOT(ISNUMBER(O12)),"N/A",IF(P12<0,"EXPIRED",IF(P12<=cfg_ExpiryWarn,"EXPIRING","OK")))) | R12: =IF(OR($C12="",L12=""),"",SUMIFS(RC_Qty,RC_Prod,'_Engine'!E8,RC_Date,">"&L12)) | S12: ='_Engine'!AC8 | T12: ='_Engine'!AD8
B13: ='_Engine'!B9 | C13: ='_Engine'!C9 | D13: ='_Engine'!D9 | E13: ='_Engine'!G9 | F13: =IF(OR($C13="",N13=0),"",INDEX(CL_Count,MATCH('_Engine'!E9&"|1",CL_Key,0))) | G13: =IF(OR($C13="",N13=0),"",INDEX(CL_Count,MATCH('_Engine'!E9&"|"&N13,CL_Key,0))) | H13: =IF(OR($C13="",G13=""),"",G13+N(R13)) | I13: =IF(OR(H13="",E13="",N(E13)=0),"",H13/E13) | J13: =IF($C13="","",IF(H13="","NO COUNT",IF(OR(E13="",N(E13)=0),"NO PAR",IF(I13<=cfg_Crit,"CRITICAL",IF(I13<=cfg_Low,"LOW","OK"))))) | K13: =IF(OR($C13="",H13="",E13=""),"",MAX(0,E13-H13)) | L13: =IF(OR($C13="",N13=0),"",INDEX(CL_Date,MATCH('_Engine'!E9&"|"&N13,CL_Key,0))) | M13: ='_Engine'!F9 | N13: =IF($C13="","",COUNTIFS(CL_Prod,'_Engine'!E9,CL_Count,"<>")) | O13: ='_Engine'!L9 | P13: =IF(ISNUMBER(O13),O13-cfg_AsOf,"") | Q13: =IF($C13="","",IF(NOT(ISNUMBER(O13)),"N/A",IF(P13<0,"EXPIRED",IF(P13<=cfg_ExpiryWarn,"EXPIRING","OK")))) | R13: =IF(OR($C13="",L13=""),"",SUMIFS(RC_Qty,RC_Prod,'_Engine'!E9,RC_Date,">"&L13)) | S13: ='_Engine'!AC9 | T13: ='_Engine'!AD9
B14: ='_Engine'!B10 | C14: ='_Engine'!C10 | D14: ='_Engine'!D10 | E14: ='_Engine'!G10 | F14: =IF(OR($C14="",N14=0),"",INDEX(CL_Count,MATCH('_Engine'!E10&"|1",CL_Key,0))) | G14: =IF(OR($C14="",N14=0),"",INDEX(CL_Count,MATCH('_Engine'!E10&"|"&N14,CL_Key,0))) | H14: =IF(OR($C14="",G14=""),"",G14+N(R14)) | I14: =IF(OR(H14="",E14="",N(E14)=0),"",H14/E14) | J14: =IF($C14="","",IF(H14="","NO COUNT",IF(OR(E14="",N(E14)=0),"NO PAR",IF(I14<=cfg_Crit,"CRITICAL",IF(I14<=cfg_Low,"LOW","OK"))))) | K14: =IF(OR($C14="",H14="",E14=""),"",MAX(0,E14-H14)) | L14: =IF(OR($C14="",N14=0),"",INDEX(CL_Date,MATCH('_Engine'!E10&"|"&N14,CL_Key,0))) | M14: ='_Engine'!F10 | N14: =IF($C14="","",COUNTIFS(CL_Prod,'_Engine'!E10,CL_Count,"<>")) | O14: ='_Engine'!L10 | P14: =IF(ISNUMBER(O14),O14-cfg_AsOf,"") | Q14: =IF($C14="","",IF(NOT(ISNUMBER(O14)),"N/A",IF(P14<0,"EXPIRED",IF(P14<=cfg_ExpiryWarn,"EXPIRING","OK")))) | R14: =IF(OR($C14="",L14=""),"",SUMIFS(RC_Qty,RC_Prod,'_Engine'!E10,RC_Date,">"&L14)) | S14: ='_Engine'!AC10 | T14: ='_Engine'!AD10
B15: ='_Engine'!B11 | C15: ='_Engine'!C11 | D15: ='_Engine'!D11 | E15: ='_Engine'!G11 | F15: =IF(OR($C15="",N15=0),"",INDEX(CL_Count,MATCH('_Engine'!E11&"|1",CL_Key,0))) | G15: =IF(OR($C15="",N15=0),"",INDEX(CL_Count,MATCH('_Engine'!E11&"|"&N15,CL_Key,0))) | H15: =IF(OR($C15="",G15=""),"",G15+N(R15)) | I15: =IF(OR(H15="",E15="",N(E15)=0),"",H15/E15) | J15: =IF($C15="","",IF(H15="","NO COUNT",IF(OR(E15="",N(E15)=0),"NO PAR",IF(I15<=cfg_Crit,"CRITICAL",IF(I15<=cfg_Low,"LOW","OK"))))) | K15: =IF(OR($C15="",H15="",E15=""),"",MAX(0,E15-H15)) | L15: =IF(OR($C15="",N15=0),"",INDEX(CL_Date,MATCH('_Engine'!E11&"|"&N15,CL_Key,0))) | M15: ='_Engine'!F11 | N15: =IF($C15="","",COUNTIFS(CL_Prod,'_Engine'!E11,CL_Count,"<>")) | O15: ='_Engine'!L11 | P15: =IF(ISNUMBER(O15),O15-cfg_AsOf,"") | Q15: =IF($C15="","",IF(NOT(ISNUMBER(O15)),"N/A",IF(P15<0,"EXPIRED",IF(P15<=cfg_ExpiryWarn,"EXPIRING","OK")))) | R15: =IF(OR($C15="",L15=""),"",SUMIFS(RC_Qty,RC_Prod,'_Engine'!E11,RC_Date,">"&L15)) | S15: ='_Engine'!AC11 | T15: ='_Engine'!AD11
B16: ='_Engine'!B12 | C16: ='_Engine'!C12 | D16: ='_Engine'!D12 | E16: ='_Engine'!G12 | F16: =IF(OR($C16="",N16=0),"",INDEX(CL_Count,MATCH('_Engine'!E12&"|1",CL_Key,0))) | G16: =IF(OR($C16="",N16=0),"",INDEX(CL_Count,MATCH('_Engine'!E12&"|"&N16,CL_Key,0))) | H16: =IF(OR($C16="",G16=""),"",G16+N(R16)) | I16: =IF(OR(H16="",E16="",N(E16)=0),"",H16/E16) | J16: =IF($C16="","",IF(H16="","NO COUNT",IF(OR(E16="",N(E16)=0),"NO PAR",IF(I16<=cfg_Crit,"CRITICAL",IF(I16<=cfg_Low,"LOW","OK"))))) | K16: =IF(OR($C16="",H16="",E16=""),"",MAX(0,E16-H16)) | L16: =IF(OR($C16="",N16=0),"",INDEX(CL_Date,MATCH('_Engine'!E12&"|"&N16,CL_Key,0))) | M16: ='_Engine'!F12 | N16: =IF($C16="","",COUNTIFS(CL_Prod,'_Engine'!E12,CL_Count,"<>")) | O16: ='_Engine'!L12 | P16: =IF(ISNUMBER(O16),O16-cfg_AsOf,"") | Q16: =IF($C16="","",IF(NOT(ISNUMBER(O16)),"N/A",IF(P16<0,"EXPIRED",IF(P16<=cfg_ExpiryWarn,"EXPIRING","OK")))) | R16: =IF(OR($C16="",L16=""),"",SUMIFS(RC_Qty,RC_Prod,'_Engine'!E12,RC_Date,">"&L16)) | S16: ='_Engine'!AC12 | T16: ='_Engine'!AD12
B17: ='_Engine'!B13 | C17: ='_Engine'!C13 | D17: ='_Engine'!D13 | E17: ='_Engine'!G13 | F17: =IF(OR($C17="",N17=0),"",INDEX(CL_Count,MATCH('_Engine'!E13&"|1",CL_Key,0))) | G17: =IF(OR($C17="",N17=0),"",INDEX(CL_Count,MATCH('_Engine'!E13&"|"&N17,CL_Key,0))) | H17: =IF(OR($C17="",G17=""),"",G17+N(R17)) | I17: =IF(OR(H17="",E17="",N(E17)=0),"",H17/E17) | J17: =IF($C17="","",IF(H17="","NO COUNT",IF(OR(E17="",N(E17)=0),"NO PAR",IF(I17<=cfg_Crit,"CRITICAL",IF(I17<=cfg_Low,"LOW","OK"))))) | K17: =IF(OR($C17="",H17="",E17=""),"",MAX(0,E17-H17)) | L17: =IF(OR($C17="",N17=0),"",INDEX(CL_Date,MATCH('_Engine'!E13&"|"&N17,CL_Key,0))) | M17: ='_Engine'!F13 | N17: =IF($C17="","",COUNTIFS(CL_Prod,'_Engine'!E13,CL_Count,"<>")) | O17: ='_Engine'!L13 | P17: =IF(ISNUMBER(O17),O17-cfg_AsOf,"") | Q17: =IF($C17="","",IF(NOT(ISNUMBER(O17)),"N/A",IF(P17<0,"EXPIRED",IF(P17<=cfg_ExpiryWarn,"EXPIRING","OK")))) | R17: =IF(OR($C17="",L17=""),"",SUMIFS(RC_Qty,RC_Prod,'_Engine'!E13,RC_Date,">"&L17)) | S17: ='_Engine'!AC13 | T17: ='_Engine'!AD13
... B305: ='_Engine'!B301 | C305: ='_Engine'!C301 | D305: ='_Engine'!D301 | E305: ='_Engine'!G301 | F305: =IF(OR($C305="",N305=0),"",INDEX(CL_Count,MATCH('_Engine'!E301&"|1",CL_Key,0))) | G305: =IF(OR($C305="",N305=0),"",INDEX(CL_Count,MATCH('_Engine'!E301&"|"&N305,CL_Key,0))) | H305: =IF(OR($C305="",G305=""),"",G305+N(R305)) | I305: =IF(OR(H305="",E305="",N(E305)=0),"",H305/E305) | J305: =IF($C305="","",IF(H305="","NO COUNT",IF(OR(E305="",N(E305)=0),"NO PAR",IF(I305<=cfg_Crit,"CRITICAL",IF(I305<=cfg_Low,"LOW","OK"))))) | K305: =IF(OR($C305="",H305="",E305=""),"",MAX(0,E305-H305)) | L305: =IF(OR($C305="",N305=0),"",INDEX(CL_Date,MATCH('_Engine'!E301&"|"&N305,CL_Key,0))) | M305: ='_Engine'!F301 | N305: =IF($C305="","",COUNTIFS(CL_Prod,'_Engine'!E301,CL_Count,"<>")) | O305: ='_Engine'!L301 | P305: =IF(ISNUMBER(O305),O305-cfg_AsOf,"") | Q305: =IF($C305="","",IF(NOT(ISNUMBER(O305)),"N/A",IF(P305<0,"EXPIRED",IF(P305<=cfg_ExpiryWarn,"EXPIRING","OK")))) | R305: =IF(OR($C305="",L305=""),"",SUMIFS(RC_Qty,RC_Prod,'_Engine'!E301,RC_Date,">"&L305)) | S305: ='_Engine'!AC301 | T305: ='_Engine'!AD301

Sheet Weekly Count
B1: =cfg_Site&" Operations Hub · Inventory Management" | Q1: =cfg_AsOf
B2: ⌂ HOME | D2: ⚙ CONTROL | E2: INVENTORY | F2: ✎ COUNT | G2: ✎ RECEIVE | H2: ORDERS | I2: ◧ INV. DASH | J2: PILOT ITEMS | L2: ✎ RESTOCK | M2: ✎ FEEDBACK | Q2: ◧ PILOT DASH | R2: ✎ TASKS
B3: Weekly physical count — type only the BLUE columns: date, pick the product, the quantity on the shelf and who counted. Add new counts at the bottom (oldest first). Everything else fills itself and feeds the Inventory Master.
B5: Count Date | C5: Week # | D5: Product | E5: Item # | F5: Physical Count | G5: Prior Count | H5: Weekly Usage | I5: Counted By | J5: PAR Level | K5: Variance to PAR | L5: Status | M5: Month | N5: Record ID | O5: Key | P5: Seq
C6: =IF(B6="","",WEEKNUM(B6,21)) | E6: =IF(D6="","",IFERROR(INDEX(Eng_Item,MATCH(D6,Eng_Label,0)),"not in list")) | G6: =IF(OR(P6="",N(P6)<=1),"",INDEX($F$6:$F$3005,MATCH(D6&"|"&(P6-1),$O$6:$O$3005,0))) | H6: =IF(G6="","",MAX(0,G6-F6)) | J6: =IF(D6="","",IFERROR(INDEX(Eng_PAR,MATCH(D6,Eng_Label,0)),"")) | K6: =IF(OR(F6="",J6=""),"",F6-J6) | L6: =IF(OR(F6="",J6="",N(J6)=0),"",IF(F6/J6<=cfg_Crit,"CRITICAL",IF(F6/J6<=cfg_Low,"LOW","OK"))) | M6: =IF(B6="","",DATE(YEAR(B6),MONTH(B6),1)) | N6: =IF(OR(B6="",D6=""),"","CNT-"&TEXT(ROW()-5,"00000")) | O6: =IF(P6="","",D6&"|"&P6) | P6: =IF(OR(D6="",F6=""),"",COUNTIFS($D$6:D6,D6,$F$6:F6,"<>"))
C7: =IF(B7="","",WEEKNUM(B7,21)) | E7: =IF(D7="","",IFERROR(INDEX(Eng_Item,MATCH(D7,Eng_Label,0)),"not in list")) | G7: =IF(OR(P7="",N(P7)<=1),"",INDEX($F$6:$F$3005,MATCH(D7&"|"&(P7-1),$O$6:$O$3005,0))) | H7: =IF(G7="","",MAX(0,G7-F7)) | J7: =IF(D7="","",IFERROR(INDEX(Eng_PAR,MATCH(D7,Eng_Label,0)),"")) | K7: =IF(OR(F7="",J7=""),"",F7-J7) | L7: =IF(OR(F7="",J7="",N(J7)=0),"",IF(F7/J7<=cfg_Crit,"CRITICAL",IF(F7/J7<=cfg_Low,"LOW","OK"))) | M7: =IF(B7="","",DATE(YEAR(B7),MONTH(B7),1)) | N7: =IF(OR(B7="",D7=""),"","CNT-"&TEXT(ROW()-5,"00000")) | O7: =IF(P7="","",D7&"|"&P7) | P7: =IF(OR(D7="",F7=""),"",COUNTIFS($D$6:D7,D7,$F$6:F7,"<>"))
C8: =IF(B8="","",WEEKNUM(B8,21)) | E8: =IF(D8="","",IFERROR(INDEX(Eng_Item,MATCH(D8,Eng_Label,0)),"not in list")) | G8: =IF(OR(P8="",N(P8)<=1),"",INDEX($F$6:$F$3005,MATCH(D8&"|"&(P8-1),$O$6:$O$3005,0))) | H8: =IF(G8="","",MAX(0,G8-F8)) | J8: =IF(D8="","",IFERROR(INDEX(Eng_PAR,MATCH(D8,Eng_Label,0)),"")) | K8: =IF(OR(F8="",J8=""),"",F8-J8) | L8: =IF(OR(F8="",J8="",N(J8)=0),"",IF(F8/J8<=cfg_Crit,"CRITICAL",IF(F8/J8<=cfg_Low,"LOW","OK"))) | M8: =IF(B8="","",DATE(YEAR(B8),MONTH(B8),1)) | N8: =IF(OR(B8="",D8=""),"","CNT-"&TEXT(ROW()-5,"00000")) | O8: =IF(P8="","",D8&"|"&P8) | P8: =IF(OR(D8="",F8=""),"",COUNTIFS($D$6:D8,D8,$F$6:F8,"<>"))
C9: =IF(B9="","",WEEKNUM(B9,21)) | E9: =IF(D9="","",IFERROR(INDEX(Eng_Item,MATCH(D9,Eng_Label,0)),"not in list")) | G9: =IF(OR(P9="",N(P9)<=1),"",INDEX($F$6:$F$3005,MATCH(D9&"|"&(P9-1),$O$6:$O$3005,0))) | H9: =IF(G9="","",MAX(0,G9-F9)) | J9: =IF(D9="","",IFERROR(INDEX(Eng_PAR,MATCH(D9,Eng_Label,0)),"")) | K9: =IF(OR(F9="",J9=""),"",F9-J9) | L9: =IF(OR(F9="",J9="",N(J9)=0),"",IF(F9/J9<=cfg_Crit,"CRITICAL",IF(F9/J9<=cfg_Low,"LOW","OK"))) | M9: =IF(B9="","",DATE(YEAR(B9),MONTH(B9),1)) | N9: =IF(OR(B9="",D9=""),"","CNT-"&TEXT(ROW()-5,"00000")) | O9: =IF(P9="","",D9&"|"&P9) | P9: =IF(OR(D9="",F9=""),"",COUNTIFS($D$6:D9,D9,$F$6:F9,"<>"))
C10: =IF(B10="","",WEEKNUM(B10,21)) | E10: =IF(D10="","",IFERROR(INDEX(Eng_Item,MATCH(D10,Eng_Label,0)),"not in list")) | G10: =IF(OR(P10="",N(P10)<=1),"",INDEX($F$6:$F$3005,MATCH(D10&"|"&(P10-1),$O$6:$O$3005,0))) | H10: =IF(G10="","",MAX(0,G10-F10)) | J10: =IF(D10="","",IFERROR(INDEX(Eng_PAR,MATCH(D10,Eng_Label,0)),"")) | K10: =IF(OR(F10="",J10=""),"",F10-J10) | L10: =IF(OR(F10="",J10="",N(J10)=0),"",IF(F10/J10<=cfg_Crit,"CRITICAL",IF(F10/J10<=cfg_Low,"LOW","OK"))) | M10: =IF(B10="","",DATE(YEAR(B10),MONTH(B10),1)) | N10: =IF(OR(B10="",D10=""),"","CNT-"&TEXT(ROW()-5,"00000")) | O10: =IF(P10="","",D10&"|"&P10) | P10: =IF(OR(D10="",F10=""),"",COUNTIFS($D$6:D10,D10,$F$6:F10,"<>"))
C11: =IF(B11="","",WEEKNUM(B11,21)) | E11: =IF(D11="","",IFERROR(INDEX(Eng_Item,MATCH(D11,Eng_Label,0)),"not in list")) | G11: =IF(OR(P11="",N(P11)<=1),"",INDEX($F$6:$F$3005,MATCH(D11&"|"&(P11-1),$O$6:$O$3005,0))) | H11: =IF(G11="","",MAX(0,G11-F11)) | J11: =IF(D11="","",IFERROR(INDEX(Eng_PAR,MATCH(D11,Eng_Label,0)),"")) | K11: =IF(OR(F11="",J11=""),"",F11-J11) | L11: =IF(OR(F11="",J11="",N(J11)=0),"",IF(F11/J11<=cfg_Crit,"CRITICAL",IF(F11/J11<=cfg_Low,"LOW","OK"))) | M11: =IF(B11="","",DATE(YEAR(B11),MONTH(B11),1)) | N11: =IF(OR(B11="",D11=""),"","CNT-"&TEXT(ROW()-5,"00000")) | O11: =IF(P11="","",D11&"|"&P11) | P11: =IF(OR(D11="",F11=""),"",COUNTIFS($D$6:D11,D11,$F$6:F11,"<>"))
C12: =IF(B12="","",WEEKNUM(B12,21)) | E12: =IF(D12="","",IFERROR(INDEX(Eng_Item,MATCH(D12,Eng_Label,0)),"not in list")) | G12: =IF(OR(P12="",N(P12)<=1),"",INDEX($F$6:$F$3005,MATCH(D12&"|"&(P12-1),$O$6:$O$3005,0))) | H12: =IF(G12="","",MAX(0,G12-F12)) | J12: =IF(D12="","",IFERROR(INDEX(Eng_PAR,MATCH(D12,Eng_Label,0)),"")) | K12: =IF(OR(F12="",J12=""),"",F12-J12) | L12: =IF(OR(F12="",J12="",N(J12)=0),"",IF(F12/J12<=cfg_Crit,"CRITICAL",IF(F12/J12<=cfg_Low,"LOW","OK"))) | M12: =IF(B12="","",DATE(YEAR(B12),MONTH(B12),1)) | N12: =IF(OR(B12="",D12=""),"","CNT-"&TEXT(ROW()-5,"00000")) | O12: =IF(P12="","",D12&"|"&P12) | P12: =IF(OR(D12="",F12=""),"",COUNTIFS($D$6:D12,D12,$F$6:F12,"<>"))
C13: =IF(B13="","",WEEKNUM(B13,21)) | E13: =IF(D13="","",IFERROR(INDEX(Eng_Item,MATCH(D13,Eng_Label,0)),"not in list")) | G13: =IF(OR(P13="",N(P13)<=1),"",INDEX($F$6:$F$3005,MATCH(D13&"|"&(P13-1),$O$6:$O$3005,0))) | H13: =IF(G13="","",MAX(0,G13-F13)) | J13: =IF(D13="","",IFERROR(INDEX(Eng_PAR,MATCH(D13,Eng_Label,0)),"")) | K13: =IF(OR(F13="",J13=""),"",F13-J13) | L13: =IF(OR(F13="",J13="",N(J13)=0),"",IF(F13/J13<=cfg_Crit,"CRITICAL",IF(F13/J13<=cfg_Low,"LOW","OK"))) | M13: =IF(B13="","",DATE(YEAR(B13),MONTH(B13),1)) | N13: =IF(OR(B13="",D13=""),"","CNT-"&TEXT(ROW()-5,"00000")) | O13: =IF(P13="","",D13&"|"&P13) | P13: =IF(OR(D13="",F13=""),"",COUNTIFS($D$6:D13,D13,$F$6:F13,"<>"))
C14: =IF(B14="","",WEEKNUM(B14,21)) | E14: =IF(D14="","",IFERROR(INDEX(Eng_Item,MATCH(D14,Eng_Label,0)),"not in list")) | G14: =IF(OR(P14="",N(P14)<=1),"",INDEX($F$6:$F$3005,MATCH(D14&"|"&(P14-1),$O$6:$O$3005,0))) | H14: =IF(G14="","",MAX(0,G14-F14)) | J14: =IF(D14="","",IFERROR(INDEX(Eng_PAR,MATCH(D14,Eng_Label,0)),"")) | K14: =IF(OR(F14="",J14=""),"",F14-J14) | L14: =IF(OR(F14="",J14="",N(J14)=0),"",IF(F14/J14<=cfg_Crit,"CRITICAL",IF(F14/J14<=cfg_Low,"LOW","OK"))) | M14: =IF(B14="","",DATE(YEAR(B14),MONTH(B14),1)) | N14: =IF(OR(B14="",D14=""),"","CNT-"&TEXT(ROW()-5,"00000")) | O14: =IF(P14="","",D14&"|"&P14) | P14: =IF(OR(D14="",F14=""),"",COUNTIFS($D$6:D14,D14,$F$6:F14,"<>"))
C15: =IF(B15="","",WEEKNUM(B15,21)) | E15: =IF(D15="","",IFERROR(INDEX(Eng_Item,MATCH(D15,Eng_Label,0)),"not in list")) | G15: =IF(OR(P15="",N(P15)<=1),"",INDEX($F$6:$F$3005,MATCH(D15&"|"&(P15-1),$O$6:$O$3005,0))) | H15: =IF(G15="","",MAX(0,G15-F15)) | J15: =IF(D15="","",IFERROR(INDEX(Eng_PAR,MATCH(D15,Eng_Label,0)),"")) | K15: =IF(OR(F15="",J15=""),"",F15-J15) | L15: =IF(OR(F15="",J15="",N(J15)=0),"",IF(F15/J15<=cfg_Crit,"CRITICAL",IF(F15/J15<=cfg_Low,"LOW","OK"))) | M15: =IF(B15="","",DATE(YEAR(B15),MONTH(B15),1)) | N15: =IF(OR(B15="",D15=""),"","CNT-"&TEXT(ROW()-5,"00000")) | O15: =IF(P15="","",D15&"|"&P15) | P15: =IF(OR(D15="",F15=""),"",COUNTIFS($D$6:D15,D15,$F$6:F15,"<>"))
C16: =IF(B16="","",WEEKNUM(B16,21)) | E16: =IF(D16="","",IFERROR(INDEX(Eng_Item,MATCH(D16,Eng_Label,0)),"not in list")) | G16: =IF(OR(P16="",N(P16)<=1),"",INDEX($F$6:$F$3005,MATCH(D16&"|"&(P16-1),$O$6:$O$3005,0))) | H16: =IF(G16="","",MAX(0,G16-F16)) | J16: =IF(D16="","",IFERROR(INDEX(Eng_PAR,MATCH(D16,Eng_Label,0)),"")) | K16: =IF(OR(F16="",J16=""),"",F16-J16) | L16: =IF(OR(F16="",J16="",N(J16)=0),"",IF(F16/J16<=cfg_Crit,"CRITICAL",IF(F16/J16<=cfg_Low,"LOW","OK"))) | M16: =IF(B16="","",DATE(YEAR(B16),MONTH(B16),1)) | N16: =IF(OR(B16="",D16=""),"","CNT-"&TEXT(ROW()-5,"00000")) | O16: =IF(P16="","",D16&"|"&P16) | P16: =IF(OR(D16="",F16=""),"",COUNTIFS($D$6:D16,D16,$F$6:F16,"<>"))
C17: =IF(B17="","",WEEKNUM(B17,21)) | E17: =IF(D17="","",IFERROR(INDEX(Eng_Item,MATCH(D17,Eng_Label,0)),"not in list")) | G17: =IF(OR(P17="",N(P17)<=1),"",INDEX($F$6:$F$3005,MATCH(D17&"|"&(P17-1),$O$6:$O$3005,0))) | H17: =IF(G17="","",MAX(0,G17-F17)) | J17: =IF(D17="","",IFERROR(INDEX(Eng_PAR,MATCH(D17,Eng_Label,0)),"")) | K17: =IF(OR(F17="",J17=""),"",F17-J17) | L17: =IF(OR(F17="",J17="",N(J17)=0),"",IF(F17/J17<=cfg_Crit,"CRITICAL",IF(F17/J17<=cfg_Low,"LOW","OK"))) | M17: =IF(B17="","",DATE(YEAR(B17),MONTH(B17),1)) | N17: =IF(OR(B17="",D17=""),"","CNT-"&TEXT(ROW()-5,"00000")) | O17: =IF(P17="","",D17&"|"&P17) | P17: =IF(OR(D17="",F17=""),"",COUNTIFS($D$6:D17,D17,$F$6:F17,"<>"))
... C3005: =IF(B3005="","",WEEKNUM(B3005,21)) | E3005: =IF(D3005="","",IFERROR(INDEX(Eng_Item,MATCH(D3005,Eng_Label,0)),"not in list")) | G3005: =IF(OR(P3005="",N(P3005)<=1),"",INDEX($F$6:$F$3005,MATCH(D3005&"|"&(P3005-1),$O$6:$O$3005,0))) | H3005: =IF(G3005="","",MAX(0,G3005-F3005)) | J3005: =IF(D3005="","",IFERROR(INDEX(Eng_PAR,MATCH(D3005,Eng_Label,0)),"")) | K3005: =IF(OR(F3005="",J3005=""),"",F3005-J3005) | L3005: =IF(OR(F3005="",J3005="",N(J3005)=0),"",IF(F3005/J3005<=cfg_Crit,"CRITICAL",IF(F3005/J3005<=cfg_Low,"LOW","OK"))) | M3005: =IF(B3005="","",DATE(YEAR(B3005),MONTH(B3005),1)) | N3005: =IF(OR(B3005="",D3005=""),"","CNT-"&TEXT(ROW()-5,"00000")) | O3005: =IF(P3005="","",D3005&"|"&P3005) | P3005: =IF(OR(D3005="",F3005=""),"",COUNTIFS($D$6:D3005,D3005,$F$6:F3005,"<>"))

Sheet Receiving Log
B1: =cfg_Site&" Operations Hub · Inventory Management" | O1: =cfg_AsOf
B2: ⌂ HOME | D2: ⚙ CONTROL | E2: INVENTORY | F2: ✎ COUNT | G2: ✎ RECEIVE | H2: ORDERS | I2: ◧ INV. DASH | J2: PILOT ITEMS | K2: ✎ RESTOCK | M2: ✎ FEEDBACK | N2: ◧ PILOT DASH | P2: ✎ TASKS
B3: Log every delivery — type only the BLUE columns. Units received after a product's last count are added to its Current Stock. Leave Unit Cost empty to use the cost from Source Data.
B5: Date Received | C5: Product | D5: Item # | E5: Supplier | F5: Qty Received | G5: Unit Cost | H5: Line Cost | I5: PO / Reference | J5: Received By | K5: Month | L5: Record ID
D6: =IF(C6="","",IFERROR(INDEX(Eng_Item,MATCH(C6,Eng_Label,0)),"not in list")) | E6: =IF(C6="","",IFERROR(INDEX(Eng_Supplier,MATCH(C6,Eng_Label,0)),"")) | H6: =IF(F6="","",F6*IF(G6<>"",G6,N(IFERROR(INDEX(Eng_Cost,MATCH(C6,Eng_Label,0)),0)))) | K6: =IF(B6="","",DATE(YEAR(B6),MONTH(B6),1)) | L6: =IF(OR(B6="",C6=""),"","RCV-"&TEXT(ROW()-5,"00000"))
D7: =IF(C7="","",IFERROR(INDEX(Eng_Item,MATCH(C7,Eng_Label,0)),"not in list")) | E7: =IF(C7="","",IFERROR(INDEX(Eng_Supplier,MATCH(C7,Eng_Label,0)),"")) | H7: =IF(F7="","",F7*IF(G7<>"",G7,N(IFERROR(INDEX(Eng_Cost,MATCH(C7,Eng_Label,0)),0)))) | K7: =IF(B7="","",DATE(YEAR(B7),MONTH(B7),1)) | L7: =IF(OR(B7="",C7=""),"","RCV-"&TEXT(ROW()-5,"00000"))
D8: =IF(C8="","",IFERROR(INDEX(Eng_Item,MATCH(C8,Eng_Label,0)),"not in list")) | E8: =IF(C8="","",IFERROR(INDEX(Eng_Supplier,MATCH(C8,Eng_Label,0)),"")) | H8: =IF(F8="","",F8*IF(G8<>"",G8,N(IFERROR(INDEX(Eng_Cost,MATCH(C8,Eng_Label,0)),0)))) | K8: =IF(B8="","",DATE(YEAR(B8),MONTH(B8),1)) | L8: =IF(OR(B8="",C8=""),"","RCV-"&TEXT(ROW()-5,"00000"))
D9: =IF(C9="","",IFERROR(INDEX(Eng_Item,MATCH(C9,Eng_Label,0)),"not in list")) | E9: =IF(C9="","",IFERROR(INDEX(Eng_Supplier,MATCH(C9,Eng_Label,0)),"")) | H9: =IF(F9="","",F9*IF(G9<>"",G9,N(IFERROR(INDEX(Eng_Cost,MATCH(C9,Eng_Label,0)),0)))) | K9: =IF(B9="","",DATE(YEAR(B9),MONTH(B9),1)) | L9: =IF(OR(B9="",C9=""),"","RCV-"&TEXT(ROW()-5,"00000"))
D10: =IF(C10="","",IFERROR(INDEX(Eng_Item,MATCH(C10,Eng_Label,0)),"not in list")) | E10: =IF(C10="","",IFERROR(INDEX(Eng_Supplier,MATCH(C10,Eng_Label,0)),"")) | H10: =IF(F10="","",F10*IF(G10<>"",G10,N(IFERROR(INDEX(Eng_Cost,MATCH(C10,Eng_Label,0)),0)))) | K10: =IF(B10="","",DATE(YEAR(B10),MONTH(B10),1)) | L10: =IF(OR(B10="",C10=""),"","RCV-"&TEXT(ROW()-5,"00000"))
D11: =IF(C11="","",IFERROR(INDEX(Eng_Item,MATCH(C11,Eng_Label,0)),"not in list")) | E11: =IF(C11="","",IFERROR(INDEX(Eng_Supplier,MATCH(C11,Eng_Label,0)),"")) | H11: =IF(F11="","",F11*IF(G11<>"",G11,N(IFERROR(INDEX(Eng_Cost,MATCH(C11,Eng_Label,0)),0)))) | K11: =IF(B11="","",DATE(YEAR(B11),MONTH(B11),1)) | L11: =IF(OR(B11="",C11=""),"","RCV-"&TEXT(ROW()-5,"00000"))
D12: =IF(C12="","",IFERROR(INDEX(Eng_Item,MATCH(C12,Eng_Label,0)),"not in list")) | E12: =IF(C12="","",IFERROR(INDEX(Eng_Supplier,MATCH(C12,Eng_Label,0)),"")) | H12: =IF(F12="","",F12*IF(G12<>"",G12,N(IFERROR(INDEX(Eng_Cost,MATCH(C12,Eng_Label,0)),0)))) | K12: =IF(B12="","",DATE(YEAR(B12),MONTH(B12),1)) | L12: =IF(OR(B12="",C12=""),"","RCV-"&TEXT(ROW()-5,"00000"))
D13: =IF(C13="","",IFERROR(INDEX(Eng_Item,MATCH(C13,Eng_Label,0)),"not in list")) | E13: =IF(C13="","",IFERROR(INDEX(Eng_Supplier,MATCH(C13,Eng_Label,0)),"")) | H13: =IF(F13="","",F13*IF(G13<>"",G13,N(IFERROR(INDEX(Eng_Cost,MATCH(C13,Eng_Label,0)),0)))) | K13: =IF(B13="","",DATE(YEAR(B13),MONTH(B13),1)) | L13: =IF(OR(B13="",C13=""),"","RCV-"&TEXT(ROW()-5,"00000"))
D14: =IF(C14="","",IFERROR(INDEX(Eng_Item,MATCH(C14,Eng_Label,0)),"not in list")) | E14: =IF(C14="","",IFERROR(INDEX(Eng_Supplier,MATCH(C14,Eng_Label,0)),"")) | H14: =IF(F14="","",F14*IF(G14<>"",G14,N(IFERROR(INDEX(Eng_Cost,MATCH(C14,Eng_Label,0)),0)))) | K14: =IF(B14="","",DATE(YEAR(B14),MONTH(B14),1)) | L14: =IF(OR(B14="",C14=""),"","RCV-"&TEXT(ROW()-5,"00000"))
D15: =IF(C15="","",IFERROR(INDEX(Eng_Item,MATCH(C15,Eng_Label,0)),"not in list")) | E15: =IF(C15="","",IFERROR(INDEX(Eng_Supplier,MATCH(C15,Eng_Label,0)),"")) | H15: =IF(F15="","",F15*IF(G15<>"",G15,N(IFERROR(INDEX(Eng_Cost,MATCH(C15,Eng_Label,0)),0)))) | K15: =IF(B15="","",DATE(YEAR(B15),MONTH(B15),1)) | L15: =IF(OR(B15="",C15=""),"","RCV-"&TEXT(ROW()-5,"00000"))
D16: =IF(C16="","",IFERROR(INDEX(Eng_Item,MATCH(C16,Eng_Label,0)),"not in list")) | E16: =IF(C16="","",IFERROR(INDEX(Eng_Supplier,MATCH(C16,Eng_Label,0)),"")) | H16: =IF(F16="","",F16*IF(G16<>"",G16,N(IFERROR(INDEX(Eng_Cost,MATCH(C16,Eng_Label,0)),0)))) | K16: =IF(B16="","",DATE(YEAR(B16),MONTH(B16),1)) | L16: =IF(OR(B16="",C16=""),"","RCV-"&TEXT(ROW()-5,"00000"))
D17: =IF(C17="","",IFERROR(INDEX(Eng_Item,MATCH(C17,Eng_Label,0)),"not in list")) | E17: =IF(C17="","",IFERROR(INDEX(Eng_Supplier,MATCH(C17,Eng_Label,0)),"")) | H17: =IF(F17="","",F17*IF(G17<>"",G17,N(IFERROR(INDEX(Eng_Cost,MATCH(C17,Eng_Label,0)),0)))) | K17: =IF(B17="","",DATE(YEAR(B17),MONTH(B17),1)) | L17: =IF(OR(B17="",C17=""),"","RCV-"&TEXT(ROW()-5,"00000"))
... D1505: =IF(C1505="","",IFERROR(INDEX(Eng_Item,MATCH(C1505,Eng_Label,0)),"not in list")) | E1505: =IF(C1505="","",IFERROR(INDEX(Eng_Supplier,MATCH(C1505,Eng_Label,0)),"")) | H1505: =IF(F1505="","",F1505*IF(G1505<>"",G1505,N(IFERROR(INDEX(Eng_Cost,MATCH(C1505,Eng_Label,0)),0)))) | K1505: =IF(B1505="","",DATE(YEAR(B1505),MONTH(B1505),1)) | L1505: =IF(OR(B1505="",C1505=""),"","RCV-"&TEXT(ROW()-5,"00000"))

Sheet Order List
B1: =cfg_Site&" Operations Hub · Inventory Management" | O1: =cfg_AsOf
B2: ⌂ HOME | C2: ⚙ CONTROL | D2: INVENTORY | E2: ✎ COUNT | F2: ✎ RECEIVE | G2: ORDERS | I2: ◧ INV. DASH | K2: PILOT ITEMS | L2: ✎ RESTOCK | M2: ✎ FEEDBACK | N2: ◧ PILOT DASH | P2: ✎ TASKS
B3: Auto-generated purchase list. Use the header filters (e.g. Order Flag = ORDER, Priority = URGENT). Order Qty = PAR − Current Stock, never negative. Nothing on this page is typed by hand.
B5: Category | C5: Item Name | D5: Item # | E5: Current Stock | F5: PAR Level | G5: Order Qty | H5: Status | I5: Order Month | J5: Need-By Date | K5: Priority | L5: Order Flag | M5: Supplier | N5: Unit Cost | O5: Est. Cost
B6: ='Inventory Master'!B6 | C6: ='Inventory Master'!C6 | D6: ='Inventory Master'!D6 | E6: ='Inventory Master'!H6 | F6: ='Inventory Master'!E6 | G6: =IF($C6="","",IF(L6="ORDER",'Inventory Master'!K6,0)) | H6: ='Inventory Master'!J6 | I6: =IF($C6="","",cfg_OrderMonth) | J6: =IF(OR($C6="",L6<>"ORDER"),"",IF(K6="URGENT",cfg_AsOf+cfg_Lead,MAX(cfg_OrderMonth,cfg_AsOf)+cfg_Lead)) | K6: =IF($C6="","",IF(H6="CRITICAL","URGENT",IF(H6="LOW","STANDARD",IF(AND(cfg_ReorderOK="Yes",H6="OK",N('Inventory Master'!K6)>0),"STANDARD","NONE")))) | L6: =IF($C6="","",IF(AND(K6<>"NONE",N('Inventory Master'!K6)>0),"ORDER","NO ORDER")) | M6: ='Inventory Master'!S6 | N6: ='Inventory Master'!T6 | O6: =IF(OR($C6="",N(G6)=0,N6=""),"",G6*N6)
B7: ='Inventory Master'!B7 | C7: ='Inventory Master'!C7 | D7: ='Inventory Master'!D7 | E7: ='Inventory Master'!H7 | F7: ='Inventory Master'!E7 | G7: =IF($C7="","",IF(L7="ORDER",'Inventory Master'!K7,0)) | H7: ='Inventory Master'!J7 | I7: =IF($C7="","",cfg_OrderMonth) | J7: =IF(OR($C7="",L7<>"ORDER"),"",IF(K7="URGENT",cfg_AsOf+cfg_Lead,MAX(cfg_OrderMonth,cfg_AsOf)+cfg_Lead)) | K7: =IF($C7="","",IF(H7="CRITICAL","URGENT",IF(H7="LOW","STANDARD",IF(AND(cfg_ReorderOK="Yes",H7="OK",N('Inventory Master'!K7)>0),"STANDARD","NONE")))) | L7: =IF($C7="","",IF(AND(K7<>"NONE",N('Inventory Master'!K7)>0),"ORDER","NO ORDER")) | M7: ='Inventory Master'!S7 | N7: ='Inventory Master'!T7 | O7: =IF(OR($C7="",N(G7)=0,N7=""),"",G7*N7)
B8: ='Inventory Master'!B8 | C8: ='Inventory Master'!C8 | D8: ='Inventory Master'!D8 | E8: ='Inventory Master'!H8 | F8: ='Inventory Master'!E8 | G8: =IF($C8="","",IF(L8="ORDER",'Inventory Master'!K8,0)) | H8: ='Inventory Master'!J8 | I8: =IF($C8="","",cfg_OrderMonth) | J8: =IF(OR($C8="",L8<>"ORDER"),"",IF(K8="URGENT",cfg_AsOf+cfg_Lead,MAX(cfg_OrderMonth,cfg_AsOf)+cfg_Lead)) | K8: =IF($C8="","",IF(H8="CRITICAL","URGENT",IF(H8="LOW","STANDARD",IF(AND(cfg_ReorderOK="Yes",H8="OK",N('Inventory Master'!K8)>0),"STANDARD","NONE")))) | L8: =IF($C8="","",IF(AND(K8<>"NONE",N('Inventory Master'!K8)>0),"ORDER","NO ORDER")) | M8: ='Inventory Master'!S8 | N8: ='Inventory Master'!T8 | O8: =IF(OR($C8="",N(G8)=0,N8=""),"",G8*N8)
B9: ='Inventory Master'!B9 | C9: ='Inventory Master'!C9 | D9: ='Inventory Master'!D9 | E9: ='Inventory Master'!H9 | F9: ='Inventory Master'!E9 | G9: =IF($C9="","",IF(L9="ORDER",'Inventory Master'!K9,0)) | H9: ='Inventory Master'!J9 | I9: =IF($C9="","",cfg_OrderMonth) | J9: =IF(OR($C9="",L9<>"ORDER"),"",IF(K9="URGENT",cfg_AsOf+cfg_Lead,MAX(cfg_OrderMonth,cfg_AsOf)+cfg_Lead)) | K9: =IF($C9="","",IF(H9="CRITICAL","URGENT",IF(H9="LOW","STANDARD",IF(AND(cfg_ReorderOK="Yes",H9="OK",N('Inventory Master'!K9)>0),"STANDARD","NONE")))) | L9: =IF($C9="","",IF(AND(K9<>"NONE",N('Inventory Master'!K9)>0),"ORDER","NO ORDER")) | M9: ='Inventory Master'!S9 | N9: ='Inventory Master'!T9 | O9: =IF(OR($C9="",N(G9)=0,N9=""),"",G9*N9)
B10: ='Inventory Master'!B10 | C10: ='Inventory Master'!C10 | D10: ='Inventory Master'!D10 | E10: ='Inventory Master'!H10 | F10: ='Inventory Master'!E10 | G10: =IF($C10="","",IF(L10="ORDER",'Inventory Master'!K10,0)) | H10: ='Inventory Master'!J10 | I10: =IF($C10="","",cfg_OrderMonth) | J10: =IF(OR($C10="",L10<>"ORDER"),"",IF(K10="URGENT",cfg_AsOf+cfg_Lead,MAX(cfg_OrderMonth,cfg_AsOf)+cfg_Lead)) | K10: =IF($C10="","",IF(H10="CRITICAL","URGENT",IF(H10="LOW","STANDARD",IF(AND(cfg_ReorderOK="Yes",H10="OK",N('Inventory Master'!K10)>0),"STANDARD","NONE")))) | L10: =IF($C10="","",IF(AND(K10<>"NONE",N('Inventory Master'!K10)>0),"ORDER","NO ORDER")) | M10: ='Inventory Master'!S10 | N10: ='Inventory Master'!T10 | O10: =IF(OR($C10="",N(G10)=0,N10=""),"",G10*N10)
B11: ='Inventory Master'!B11 | C11: ='Inventory Master'!C11 | D11: ='Inventory Master'!D11 | E11: ='Inventory Master'!H11 | F11: ='Inventory Master'!E11 | G11: =IF($C11="","",IF(L11="ORDER",'Inventory Master'!K11,0)) | H11: ='Inventory Master'!J11 | I11: =IF($C11="","",cfg_OrderMonth) | J11: =IF(OR($C11="",L11<>"ORDER"),"",IF(K11="URGENT",cfg_AsOf+cfg_Lead,MAX(cfg_OrderMonth,cfg_AsOf)+cfg_Lead)) | K11: =IF($C11="","",IF(H11="CRITICAL","URGENT",IF(H11="LOW","STANDARD",IF(AND(cfg_ReorderOK="Yes",H11="OK",N('Inventory Master'!K11)>0),"STANDARD","NONE")))) | L11: =IF($C11="","",IF(AND(K11<>"NONE",N('Inventory Master'!K11)>0),"ORDER","NO ORDER")) | M11: ='Inventory Master'!S11 | N11: ='Inventory Master'!T11 | O11: =IF(OR($C11="",N(G11)=0,N11=""),"",G11*N11)
B12: ='Inventory Master'!B12 | C12: ='Inventory Master'!C12 | D12: ='Inventory Master'!D12 | E12: ='Inventory Master'!H12 | F12: ='Inventory Master'!E12 | G12: =IF($C12="","",IF(L12="ORDER",'Inventory Master'!K12,0)) | H12: ='Inventory Master'!J12 | I12: =IF($C12="","",cfg_OrderMonth) | J12: =IF(OR($C12="",L12<>"ORDER"),"",IF(K12="URGENT",cfg_AsOf+cfg_Lead,MAX(cfg_OrderMonth,cfg_AsOf)+cfg_Lead)) | K12: =IF($C12="","",IF(H12="CRITICAL","URGENT",IF(H12="LOW","STANDARD",IF(AND(cfg_ReorderOK="Yes",H12="OK",N('Inventory Master'!K12)>0),"STANDARD","NONE")))) | L12: =IF($C12="","",IF(AND(K12<>"NONE",N('Inventory Master'!K12)>0),"ORDER","NO ORDER")) | M12: ='Inventory Master'!S12 | N12: ='Inventory Master'!T12 | O12: =IF(OR($C12="",N(G12)=0,N12=""),"",G12*N12)
B13: ='Inventory Master'!B13 | C13: ='Inventory Master'!C13 | D13: ='Inventory Master'!D13 | E13: ='Inventory Master'!H13 | F13: ='Inventory Master'!E13 | G13: =IF($C13="","",IF(L13="ORDER",'Inventory Master'!K13,0)) | H13: ='Inventory Master'!J13 | I13: =IF($C13="","",cfg_OrderMonth) | J13: =IF(OR($C13="",L13<>"ORDER"),"",IF(K13="URGENT",cfg_AsOf+cfg_Lead,MAX(cfg_OrderMonth,cfg_AsOf)+cfg_Lead)) | K13: =IF($C13="","",IF(H13="CRITICAL","URGENT",IF(H13="LOW","STANDARD",IF(AND(cfg_ReorderOK="Yes",H13="OK",N('Inventory Master'!K13)>0),"STANDARD","NONE")))) | L13: =IF($C13="","",IF(AND(K13<>"NONE",N('Inventory Master'!K13)>0),"ORDER","NO ORDER")) | M13: ='Inventory Master'!S13 | N13: ='Inventory Master'!T13 | O13: =IF(OR($C13="",N(G13)=0,N13=""),"",G13*N13)
B14: ='Inventory Master'!B14 | C14: ='Inventory Master'!C14 | D14: ='Inventory Master'!D14 | E14: ='Inventory Master'!H14 | F14: ='Inventory Master'!E14 | G14: =IF($C14="","",IF(L14="ORDER",'Inventory Master'!K14,0)) | H14: ='Inventory Master'!J14 | I14: =IF($C14="","",cfg_OrderMonth) | J14: =IF(OR($C14="",L14<>"ORDER"),"",IF(K14="URGENT",cfg_AsOf+cfg_Lead,MAX(cfg_OrderMonth,cfg_AsOf)+cfg_Lead)) | K14: =IF($C14="","",IF(H14="CRITICAL","URGENT",IF(H14="LOW","STANDARD",IF(AND(cfg_ReorderOK="Yes",H14="OK",N('Inventory Master'!K14)>0),"STANDARD","NONE")))) | L14: =IF($C14="","",IF(AND(K14<>"NONE",N('Inventory Master'!K14)>0),"ORDER","NO ORDER")) | M14: ='Inventory Master'!S14 | N14: ='Inventory Master'!T14 | O14: =IF(OR($C14="",N(G14)=0,N14=""),"",G14*N14)
B15: ='Inventory Master'!B15 | C15: ='Inventory Master'!C15 | D15: ='Inventory Master'!D15 | E15: ='Inventory Master'!H15 | F15: ='Inventory Master'!E15 | G15: =IF($C15="","",IF(L15="ORDER",'Inventory Master'!K15,0)) | H15: ='Inventory Master'!J15 | I15: =IF($C15="","",cfg_OrderMonth) | J15: =IF(OR($C15="",L15<>"ORDER"),"",IF(K15="URGENT",cfg_AsOf+cfg_Lead,MAX(cfg_OrderMonth,cfg_AsOf)+cfg_Lead)) | K15: =IF($C15="","",IF(H15="CRITICAL","URGENT",IF(H15="LOW","STANDARD",IF(AND(cfg_ReorderOK="Yes",H15="OK",N('Inventory Master'!K15)>0),"STANDARD","NONE")))) | L15: =IF($C15="","",IF(AND(K15<>"NONE",N('Inventory Master'!K15)>0),"ORDER","NO ORDER")) | M15: ='Inventory Master'!S15 | N15: ='Inventory Master'!T15 | O15: =IF(OR($C15="",N(G15)=0,N15=""),"",G15*N15)
B16: ='Inventory Master'!B16 | C16: ='Inventory Master'!C16 | D16: ='Inventory Master'!D16 | E16: ='Inventory Master'!H16 | F16: ='Inventory Master'!E16 | G16: =IF($C16="","",IF(L16="ORDER",'Inventory Master'!K16,0)) | H16: ='Inventory Master'!J16 | I16: =IF($C16="","",cfg_OrderMonth) | J16: =IF(OR($C16="",L16<>"ORDER"),"",IF(K16="URGENT",cfg_AsOf+cfg_Lead,MAX(cfg_OrderMonth,cfg_AsOf)+cfg_Lead)) | K16: =IF($C16="","",IF(H16="CRITICAL","URGENT",IF(H16="LOW","STANDARD",IF(AND(cfg_ReorderOK="Yes",H16="OK",N('Inventory Master'!K16)>0),"STANDARD","NONE")))) | L16: =IF($C16="","",IF(AND(K16<>"NONE",N('Inventory Master'!K16)>0),"ORDER","NO ORDER")) | M16: ='Inventory Master'!S16 | N16: ='Inventory Master'!T16 | O16: =IF(OR($C16="",N(G16)=0,N16=""),"",G16*N16)
B17: ='Inventory Master'!B17 | C17: ='Inventory Master'!C17 | D17: ='Inventory Master'!D17 | E17: ='Inventory Master'!H17 | F17: ='Inventory Master'!E17 | G17: =IF($C17="","",IF(L17="ORDER",'Inventory Master'!K17,0)) | H17: ='Inventory Master'!J17 | I17: =IF($C17="","",cfg_OrderMonth) | J17: =IF(OR($C17="",L17<>"ORDER"),"",IF(K17="URGENT",cfg_AsOf+cfg_Lead,MAX(cfg_OrderMonth,cfg_AsOf)+cfg_Lead)) | K17: =IF($C17="","",IF(H17="CRITICAL","URGENT",IF(H17="LOW","STANDARD",IF(AND(cfg_ReorderOK="Yes",H17="OK",N('Inventory Master'!K17)>0),"STANDARD","NONE")))) | L17: =IF($C17="","",IF(AND(K17<>"NONE",N('Inventory Master'!K17)>0),"ORDER","NO ORDER")) | M17: ='Inventory Master'!S17 | N17: ='Inventory Master'!T17 | O17: =IF(OR($C17="",N(G17)=0,N17=""),"",G17*N17)
... B305: ='Inventory Master'!B305 | C305: ='Inventory Master'!C305 | D305: ='Inventory Master'!D305 | E305: ='Inventory Master'!H305 | F305: ='Inventory Master'!E305 | G305: =IF($C305="","",IF(L305="ORDER",'Inventory Master'!K305,0)) | H305: ='Inventory Master'!J305 | I305: =IF($C305="","",cfg_OrderMonth) | J305: =IF(OR($C305="",L305<>"ORDER"),"",IF(K305="URGENT",cfg_AsOf+cfg_Lead,MAX(cfg_OrderMonth,cfg_AsOf)+cfg_Lead)) | K305: =IF($C305="","",IF(H305="CRITICAL","URGENT",IF(H305="LOW","STANDARD",IF(AND(cfg_ReorderOK="Yes",H305="OK",N('Inventory Master'!K305)>0),"STANDARD","NONE")))) | L305: =IF($C305="","",IF(AND(K305<>"NONE",N('Inventory Master'!K305)>0),"ORDER","NO ORDER")) | M305: ='Inventory Master'!S305 | N305: ='Inventory Master'!T305 | O305: =IF(OR($C305="",N(G305)=0,N305=""),"",G305*N305)

Sheet Inventory Dashboard
B1: =cfg_Site&" Operations Hub · Inventory Dashboard" | O1: =cfg_AsOf
B2: ⌂ HOME | D2: ⚙ CONTROL | E2: INVENTORY | F2: ✎ COUNT | H2: ✎ RECEIVE | I2: ORDERS | J2: ◧ INV. DASH | L2: PILOT ITEMS | M2: ✎ RESTOCK | N2: ✎ FEEDBACK | P2: ◧ PILOT DASH | Q2: ✎ TASKS
B3: Live inventory health. Updates the moment a count is logged or a threshold changes on the Control Panel.
B5: TOTAL ITEMS | F5: OK ITEMS | J5: LOW ITEMS | N5: CRITICAL ITEMS
B6: =SUMPRODUCT(--(MS_Name<>"")) | F6: =COUNTIF(MS_Status,"OK") | J6: =COUNTIF(MS_Status,"LOW") | N6: =COUNTIF(MS_Status,"CRITICAL")
B7: =COUNTIF(MS_Status,"NO COUNT")&" not counted yet" | F7: ="Above "&FIXED(cfg_Low*100,0)&"% of PAR" | J7: ="≤ "&FIXED(cfg_Low*100,0)&"% of PAR" | N7: ="≤ "&FIXED(cfg_Crit*100,0)&"% of PAR"
B9: UNITS TO ORDER | F9: ITEMS TO ORDER | J9: LAST COUNT DATE | N9: STOCK HEALTH
B10: =SUM(OL_Qty) | F10: =COUNTIF(OL_Flag,"ORDER") | J10: =IF(MAX(CL_Date)=0,"No counts",MAX(CL_Date)) | N10: =IF((COUNTIF(MS_Status,"OK")+COUNTIF(MS_Status,"LOW")+COUNTIF(MS_Status,"CRITICAL"))=0,"—",COUNTIF(MS_Status,"OK")/(COUNTIF(MS_Status,"OK")+COUNTIF(MS_Status,"LOW")+COUNTIF(MS_Status,"CRITICAL")))
B11: =IF(SUM(OL_Cost)>0,"≈ $"&FIXED(SUM(OL_Cost),2)&" estimated","Add unit costs to see spend") | F11: =COUNTIF(OL_Priority,"URGENT")&" urgent" | J11: =IF(MAX(CL_Date)=0,"Log a count to start",(cfg_AsOf-MAX(CL_Date))&" days ago") | N11: ="Share of counted items at OK"
B13: STATUS MIX | I13: ORDER UNITS BY CATEGORY (top 10)
B32: STATUS MIX — DATA | I32: ORDER UNITS BY CATEGORY — DATA
B33: Status | C33: Items | E33: Share | I33: # | J33: Category | N33: Order Units | P33: Items to Order
B34: OK | C34: =COUNTIF(MS_Status,B34) | E34: =IF(SUM($C$34:$C$37)=0,"",C34/SUM($C$34:$C$37)) | I34: 1 | J34: =IF(LARGE(Cat_Score,I34)<0,"",INDEX(Cat_Name,MATCH(LARGE(Cat_Score,I34),Cat_Score,0))) | N34: =IF(J34="","",INDEX(Cat_Units,MATCH(LARGE(Cat_Score,I34),Cat_Score,0))) | P34: =IF(J34="","",INDEX('_Engine'!$Q$2:$Q$41,MATCH(LARGE(Cat_Score,I34),Cat_Score,0)))
B35: LOW | C35: =COUNTIF(MS_Status,B35) | E35: =IF(SUM($C$34:$C$37)=0,"",C35/SUM($C$34:$C$37)) | I35: 2 | J35: =IF(LARGE(Cat_Score,I35)<0,"",INDEX(Cat_Name,MATCH(LARGE(Cat_Score,I35),Cat_Score,0))) | N35: =IF(J35="","",INDEX(Cat_Units,MATCH(LARGE(Cat_Score,I35),Cat_Score,0))) | P35: =IF(J35="","",INDEX('_Engine'!$Q$2:$Q$41,MATCH(LARGE(Cat_Score,I35),Cat_Score,0)))
B36: CRITICAL | C36: =COUNTIF(MS_Status,B36) | E36: =IF(SUM($C$34:$C$37)=0,"",C36/SUM($C$34:$C$37)) | I36: 3 | J36: =IF(LARGE(Cat_Score,I36)<0,"",INDEX(Cat_Name,MATCH(LARGE(Cat_Score,I36),Cat_Score,0))) | N36: =IF(J36="","",INDEX(Cat_Units,MATCH(LARGE(Cat_Score,I36),Cat_Score,0))) | P36: =IF(J36="","",INDEX('_Engine'!$Q$2:$Q$41,MATCH(LARGE(Cat_Score,I36),Cat_Score,0)))
B37: NO COUNT | C37: =COUNTIF(MS_Status,B37) | E37: =IF(SUM($C$34:$C$37)=0,"",C37/SUM($C$34:$C$37)) | I37: 4 | J37: =IF(LARGE(Cat_Score,I37)<0,"",INDEX(Cat_Name,MATCH(LARGE(Cat_Score,I37),Cat_Score,0))) | N37: =IF(J37="","",INDEX(Cat_Units,MATCH(LARGE(Cat_Score,I37),Cat_Score,0))) | P37: =IF(J37="","",INDEX('_Engine'!$Q$2:$Q$41,MATCH(LARGE(Cat_Score,I37),Cat_Score,0)))
I38: 5 | J38: =IF(LARGE(Cat_Score,I38)<0,"",INDEX(Cat_Name,MATCH(LARGE(Cat_Score,I38),Cat_Score,0))) | N38: =IF(J38="","",INDEX(Cat_Units,MATCH(LARGE(Cat_Score,I38),Cat_Score,0))) | P38: =IF(J38="","",INDEX('_Engine'!$Q$2:$Q$41,MATCH(LARGE(Cat_Score,I38),Cat_Score,0)))
I39: 6 | J39: =IF(LARGE(Cat_Score,I39)<0,"",INDEX(Cat_Name,MATCH(LARGE(Cat_Score,I39),Cat_Score,0))) | N39: =IF(J39="","",INDEX(Cat_Units,MATCH(LARGE(Cat_Score,I39),Cat_Score,0))) | P39: =IF(J39="","",INDEX('_Engine'!$Q$2:$Q$41,MATCH(LARGE(Cat_Score,I39),Cat_Score,0)))
I40: 7 | J40: =IF(LARGE(Cat_Score,I40)<0,"",INDEX(Cat_Name,MATCH(LARGE(Cat_Score,I40),Cat_Score,0))) | N40: =IF(J40="","",INDEX(Cat_Units,MATCH(LARGE(Cat_Score,I40),Cat_Score,0))) | P40: =IF(J40="","",INDEX('_Engine'!$Q$2:$Q$41,MATCH(LARGE(Cat_Score,I40),Cat_Score,0)))
I41: 8 | J41: =IF(LARGE(Cat_Score,I41)<0,"",INDEX(Cat_Name,MATCH(LARGE(Cat_Score,I41),Cat_Score,0))) | N41: =IF(J41="","",INDEX(Cat_Units,MATCH(LARGE(Cat_Score,I41),Cat_Score,0))) | P41: =IF(J41="","",INDEX('_Engine'!$Q$2:$Q$41,MATCH(LARGE(Cat_Score,I41),Cat_Score,0)))
I42: 9 | J42: =IF(LARGE(Cat_Score,I42)<0,"",INDEX(Cat_Name,MATCH(LARGE(Cat_Score,I42),Cat_Score,0))) | N42: =IF(J42="","",INDEX(Cat_Units,MATCH(LARGE(Cat_Score,I42),Cat_Score,0))) | P42: =IF(J42="","",INDEX('_Engine'!$Q$2:$Q$41,MATCH(LARGE(Cat_Score,I42),Cat_Score,0)))
I43: 10 | J43: =IF(LARGE(Cat_Score,I43)<0,"",INDEX(Cat_Name,MATCH(LARGE(Cat_Score,I43),Cat_Score,0))) | N43: =IF(J43="","",INDEX(Cat_Units,MATCH(LARGE(Cat_Score,I43),Cat_Score,0))) | P43: =IF(J43="","",INDEX('_Engine'!$Q$2:$Q$41,MATCH(LARGE(Cat_Score,I43),Cat_Score,0)))
B46: CRITICAL & LOW WATCHLIST (lowest stock % first)
B47: # | C47: Item | G47: Category | J47: Stock % | L47: On Hand | N47: Order Qty | P47: Status
B48: 1 | C48: =IF(COUNT(Eng_Watch)>=B48,INDEX(Eng_Label,MATCH(SMALL(Eng_Watch,B48),Eng_Watch,0)),"") | G48: =IF(COUNT(Eng_Watch)>=B48,INDEX(MS_Cat,MATCH(SMALL(Eng_Watch,B48),Eng_Watch,0)),"") | J48: =IF(COUNT(Eng_Watch)>=B48,INDEX(MS_Pct,MATCH(SMALL(Eng_Watch,B48),Eng_Watch,0)),"") | L48: =IF(COUNT(Eng_Watch)>=B48,INDEX(MS_Stock,MATCH(SMALL(Eng_Watch,B48),Eng_Watch,0)),"") | N48: =IF(COUNT(Eng_Watch)>=B48,INDEX(MS_Sugg,MATCH(SMALL(Eng_Watch,B48),Eng_Watch,0)),"") | P48: =IF(COUNT(Eng_Watch)>=B48,INDEX(MS_Status,MATCH(SMALL(Eng_Watch,B48),Eng_Watch,0)),"")
B49: 2 | C49: =IF(COUNT(Eng_Watch)>=B49,INDEX(Eng_Label,MATCH(SMALL(Eng_Watch,B49),Eng_Watch,0)),"") | G49: =IF(COUNT(Eng_Watch)>=B49,INDEX(MS_Cat,MATCH(SMALL(Eng_Watch,B49),Eng_Watch,0)),"") | J49: =IF(COUNT(Eng_Watch)>=B49,INDEX(MS_Pct,MATCH(SMALL(Eng_Watch,B49),Eng_Watch,0)),"") | L49: =IF(COUNT(Eng_Watch)>=B49,INDEX(MS_Stock,MATCH(SMALL(Eng_Watch,B49),Eng_Watch,0)),"") | N49: =IF(COUNT(Eng_Watch)>=B49,INDEX(MS_Sugg,MATCH(SMALL(Eng_Watch,B49),Eng_Watch,0)),"") | P49: =IF(COUNT(Eng_Watch)>=B49,INDEX(MS_Status,MATCH(SMALL(Eng_Watch,B49),Eng_Watch,0)),"")
B50: 3 | C50: =IF(COUNT(Eng_Watch)>=B50,INDEX(Eng_Label,MATCH(SMALL(Eng_Watch,B50),Eng_Watch,0)),"") | G50: =IF(COUNT(Eng_Watch)>=B50,INDEX(MS_Cat,MATCH(SMALL(Eng_Watch,B50),Eng_Watch,0)),"") | J50: =IF(COUNT(Eng_Watch)>=B50,INDEX(MS_Pct,MATCH(SMALL(Eng_Watch,B50),Eng_Watch,0)),"") | L50: =IF(COUNT(Eng_Watch)>=B50,INDEX(MS_Stock,MATCH(SMALL(Eng_Watch,B50),Eng_Watch,0)),"") | N50: =IF(COUNT(Eng_Watch)>=B50,INDEX(MS_Sugg,MATCH(SMALL(Eng_Watch,B50),Eng_Watch,0)),"") | P50: =IF(COUNT(Eng_Watch)>=B50,INDEX(MS_Status,MATCH(SMALL(Eng_Watch,B50),Eng_Watch,0)),"")
B51: 4 | C51: =IF(COUNT(Eng_Watch)>=B51,INDEX(Eng_Label,MATCH(SMALL(Eng_Watch,B51),Eng_Watch,0)),"") | G51: =IF(COUNT(Eng_Watch)>=B51,INDEX(MS_Cat,MATCH(SMALL(Eng_Watch,B51),Eng_Watch,0)),"") | J51: =IF(COUNT(Eng_Watch)>=B51,INDEX(MS_Pct,MATCH(SMALL(Eng_Watch,B51),Eng_Watch,0)),"") | L51: =IF(COUNT(Eng_Watch)>=B51,INDEX(MS_Stock,MATCH(SMALL(Eng_Watch,B51),Eng_Watch,0)),"") | N51: =IF(COUNT(Eng_Watch)>=B51,INDEX(MS_Sugg,MATCH(SMALL(Eng_Watch,B51),Eng_Watch,0)),"") | P51: =IF(COUNT(Eng_Watch)>=B51,INDEX(MS_Status,MATCH(SMALL(Eng_Watch,B51),Eng_Watch,0)),"")
B52: 5 | C52: =IF(COUNT(Eng_Watch)>=B52,INDEX(Eng_Label,MATCH(SMALL(Eng_Watch,B52),Eng_Watch,0)),"") | G52: =IF(COUNT(Eng_Watch)>=B52,INDEX(MS_Cat,MATCH(SMALL(Eng_Watch,B52),Eng_Watch,0)),"") | J52: =IF(COUNT(Eng_Watch)>=B52,INDEX(MS_Pct,MATCH(SMALL(Eng_Watch,B52),Eng_Watch,0)),"") | L52: =IF(COUNT(Eng_Watch)>=B52,INDEX(MS_Stock,MATCH(SMALL(Eng_Watch,B52),Eng_Watch,0)),"") | N52: =IF(COUNT(Eng_Watch)>=B52,INDEX(MS_Sugg,MATCH(SMALL(Eng_Watch,B52),Eng_Watch,0)),"") | P52: =IF(COUNT(Eng_Watch)>=B52,INDEX(MS_Status,MATCH(SMALL(Eng_Watch,B52),Eng_Watch,0)),"")
B53: 6 | C53: =IF(COUNT(Eng_Watch)>=B53,INDEX(Eng_Label,MATCH(SMALL(Eng_Watch,B53),Eng_Watch,0)),"") | G53: =IF(COUNT(Eng_Watch)>=B53,INDEX(MS_Cat,MATCH(SMALL(Eng_Watch,B53),Eng_Watch,0)),"") | J53: =IF(COUNT(Eng_Watch)>=B53,INDEX(MS_Pct,MATCH(SMALL(Eng_Watch,B53),Eng_Watch,0)),"") | L53: =IF(COUNT(Eng_Watch)>=B53,INDEX(MS_Stock,MATCH(SMALL(Eng_Watch,B53),Eng_Watch,0)),"") | N53: =IF(COUNT(Eng_Watch)>=B53,INDEX(MS_Sugg,MATCH(SMALL(Eng_Watch,B53),Eng_Watch,0)),"") | P53: =IF(COUNT(Eng_Watch)>=B53,INDEX(MS_Status,MATCH(SMALL(Eng_Watch,B53),Eng_Watch,0)),"")
B54: 7 | C54: =IF(COUNT(Eng_Watch)>=B54,INDEX(Eng_Label,MATCH(SMALL(Eng_Watch,B54),Eng_Watch,0)),"") | G54: =IF(COUNT(Eng_Watch)>=B54,INDEX(MS_Cat,MATCH(SMALL(Eng_Watch,B54),Eng_Watch,0)),"") | J54: =IF(COUNT(Eng_Watch)>=B54,INDEX(MS_Pct,MATCH(SMALL(Eng_Watch,B54),Eng_Watch,0)),"") | L54: =IF(COUNT(Eng_Watch)>=B54,INDEX(MS_Stock,MATCH(SMALL(Eng_Watch,B54),Eng_Watch,0)),"") | N54: =IF(COUNT(Eng_Watch)>=B54,INDEX(MS_Sugg,MATCH(SMALL(Eng_Watch,B54),Eng_Watch,0)),"") | P54: =IF(COUNT(Eng_Watch)>=B54,INDEX(MS_Status,MATCH(SMALL(Eng_Watch,B54),Eng_Watch,0)),"")
B55: 8 | C55: =IF(COUNT(Eng_Watch)>=B55,INDEX(Eng_Label,MATCH(SMALL(Eng_Watch,B55),Eng_Watch,0)),"") | G55: =IF(COUNT(Eng_Watch)>=B55,INDEX(MS_Cat,MATCH(SMALL(Eng_Watch,B55),Eng_Watch,0)),"") | J55: =IF(COUNT(Eng_Watch)>=B55,INDEX(MS_Pct,MATCH(SMALL(Eng_Watch,B55),Eng_Watch,0)),"") | L55: =IF(COUNT(Eng_Watch)>=B55,INDEX(MS_Stock,MATCH(SMALL(Eng_Watch,B55),Eng_Watch,0)),"") | N55: =IF(COUNT(Eng_Watch)>=B55,INDEX(MS_Sugg,MATCH(SMALL(Eng_Watch,B55),Eng_Watch,0)),"") | P55: =IF(COUNT(Eng_Watch)>=B55,INDEX(MS_Status,MATCH(SMALL(Eng_Watch,B55),Eng_Watch,0)),"")
B56: 9 | C56: =IF(COUNT(Eng_Watch)>=B56,INDEX(Eng_Label,MATCH(SMALL(Eng_Watch,B56),Eng_Watch,0)),"") | G56: =IF(COUNT(Eng_Watch)>=B56,INDEX(MS_Cat,MATCH(SMALL(Eng_Watch,B56),Eng_Watch,0)),"") | J56: =IF(COUNT(Eng_Watch)>=B56,INDEX(MS_Pct,MATCH(SMALL(Eng_Watch,B56),Eng_Watch,0)),"") | L56: =IF(COUNT(Eng_Watch)>=B56,INDEX(MS_Stock,MATCH(SMALL(Eng_Watch,B56),Eng_Watch,0)),"") | N56: =IF(COUNT(Eng_Watch)>=B56,INDEX(MS_Sugg,MATCH(SMALL(Eng_Watch,B56),Eng_Watch,0)),"") | P56: =IF(COUNT(Eng_Watch)>=B56,INDEX(MS_Status,MATCH(SMALL(Eng_Watch,B56),Eng_Watch,0)),"")
B57: 10 | C57: =IF(COUNT(Eng_Watch)>=B57,INDEX(Eng_Label,MATCH(SMALL(Eng_Watch,B57),Eng_Watch,0)),"") | G57: =IF(COUNT(Eng_Watch)>=B57,INDEX(MS_Cat,MATCH(SMALL(Eng_Watch,B57),Eng_Watch,0)),"") | J57: =IF(COUNT(Eng_Watch)>=B57,INDEX(MS_Pct,MATCH(SMALL(Eng_Watch,B57),Eng_Watch,0)),"") | L57: =IF(COUNT(Eng_Watch)>=B57,INDEX(MS_Stock,MATCH(SMALL(Eng_Watch,B57),Eng_Watch,0)),"") | N57: =IF(COUNT(Eng_Watch)>=B57,INDEX(MS_Sugg,MATCH(SMALL(Eng_Watch,B57),Eng_Watch,0)),"") | P57: =IF(COUNT(Eng_Watch)>=B57,INDEX(MS_Status,MATCH(SMALL(Eng_Watch,B57),Eng_Watch,0)),"")
B58: No item is LOW or CRITICAL when this list is empty.
B60: ="EXPIRATION WATCH (soonest first) · "&COUNTIF(MS_ExpStatus,"EXPIRED")&" expired · "&COUNTIF(MS_ExpStatus,"EXPIRING")&" expiring within "&cfg_ExpiryWarn&" days"
B61: # | C61: Item | G61: Category | J61: Expiration | L61: Days Left | N61: On Hand | P61: Expiry Status
B62: 1 | C62: =IF(COUNT(Eng_Expiry)>=B62,INDEX(Eng_Label,MATCH(SMALL(Eng_Expiry,B62),Eng_Expiry,0)),"") | G62: =IF(COUNT(Eng_Expiry)>=B62,INDEX(MS_Cat,MATCH(SMALL(Eng_Expiry,B62),Eng_Expiry,0)),"") | J62: =IF(COUNT(Eng_Expiry)>=B62,INDEX(MS_Exp,MATCH(SMALL(Eng_Expiry,B62),Eng_Expiry,0)),"") | L62: =IF(COUNT(Eng_Expiry)>=B62,INDEX(MS_ExpDays,MATCH(SMALL(Eng_Expiry,B62),Eng_Expiry,0)),"") | N62: =IF(COUNT(Eng_Expiry)>=B62,INDEX(MS_Stock,MATCH(SMALL(Eng_Expiry,B62),Eng_Expiry,0)),"") | P62: =IF(COUNT(Eng_Expiry)>=B62,INDEX(MS_ExpStatus,MATCH(SMALL(Eng_Expiry,B62),Eng_Expiry,0)),"")
